Workbook
Name _: #REF!
Name dw: #REF!
Name lap: #REF!
Name sdhrhrj: #REF!
Name UC___11.1声道全景声影院系统: #REF!
Name 安泽单导: #REF!
Name 安泽双导: #REF!
Name 编制单位: ""
Name 编制人: ""
Name 编制日期: "2012年12月02日"
Name 层数高度: ""
Name 产地: OFFSET(#REF!,,,COUNTA(#REF!)-1)
Name 产品样品: OFFSET(#REF!,,,COUNTA(#REF!)-1)
Name 丹佛斯单导: #REF!
Name 丹佛斯双导: #REF!
Name 电缆: #REF!
Name 电气主材分类: OFFSET(#REF!,0,0,1,COLUMN(#REF!)-COLUMN(#REF!))
Name 饿: OFFSET(#REF!,,,COUNTA(#REF!)-1)
Name 二: OFFSET(#REF!,,,COUNT(#REF!)-1)
Name 个: OFFSET(#REF!,,,COUNT(#REF!)-1)
Name 给排水.材料分类: #REF!
Name 给排水.材料名称: OFFSET(#REF!,1,MATCH(#REF!,#REF!,0)-1,COUNTA(OFFSET(#REF!,1,MATCH(#REF!,#REF!,0)-1,500,1)),1)
Name 给排水.常用规格: OFFSET(OFFSET(#REF!,1,0),0,0,COUNTA(#REF!)+3,1)
Name 工程类别: ""
Name 工程名称: "F型房"
Name 购房人: OFFSET(#REF!,,,COUNT(#REF!)-1)
Name 规格: OFFSET(#REF!,,,COUNT(#REF!)-1)
Name 规格1: OFFSET(#REF!,,,COUNT(#REF!)-1)
Name 规格型号: #N/A
Name 和: OFFSET(#REF!,,,COUNTA(#REF!)-1)
Name 建设单位: ""
Name 建筑面积: ""
Name 结构形式: ""
Name 类别: OFFSET(#REF!,,,COUNTA(#REF!)-1)
Name 米: #REF!
Name 名称: OFFSET(#REF!,,,COUNT(#REF!)-1)
Name 名称2: OFFSET(#REF!,,,COUNT(#REF!)-1)
Name 内别1: OFFSET(#REF!,,,COUNTA(#REF!)-1)
Name 品牌: OFFSET(#REF!,,,COUNT(#REF!)-1)
Name 品牌3: OFFSET(#REF!,,,COUNT(#REF!)-1)
Name 设计单位: ""
Name 审核单位: ""
Name 资料: OFFSET(#REF!,,,COUNTA(#REF!)-1)
Name 资料1: OFFSET(#REF!,,,COUNTA(#REF!)-1)

Sheet 报价汇总
A1: Estimation of construction cost for fit-out work
A2: Project: 博彦科技深圳展厅设计施工项目
A3: Project address:深圳
A4: Issue date:2026-07-03
A5: Project code:
A7: I | B7: 项目汇总 | D7: TOTAL (RMB)
A8: 1.00 | B8: 拆除工程 | D8: =工程直接费!L9 -> 31680
A9: 2.00 | B9: 装饰工程 | D9: =D10+D11+D12+D13+D14+D15 -> 714629
A10: 2.01.00 | B10: 天花工程 | D10: =工程直接费!L12 -> 161972.42
A11: 2.02.00 | B11: 隔墙工程 | D11: =工程直接费!L23 -> 108211.68
A12: 2.03.00 | B12: 墙面工程 | D12: =工程直接费!L32 -> 131288.63
A13: 2.04.00 | B13: 地面工程 | D13: =工程直接费!L40 -> 190012.59
A14: 2.05.00 | B14: 门窗工程 | D14: =工程直接费!L48 -> 72141.64
A15: 2.06.00 | B15: 固定家具 | D15: =工程直接费!L55 -> 51002.04
A16: 3.00 | B16: 强电工程 | D16: =工程直接费!L60 -> 154080
A17: 4.00 | B17: 弱电工程 | D17: =工程直接费!L62 -> 143860.8
A18: 5.00 | B18: 空调工程 | D18: =工程直接费!L65 -> 46080
A19: 6.00 | B19: 消防工程 | D19: =工程直接费!L67 -> 48960
A20: 7.00 | B20: 措施费 | D20: =工程直接费!L69 -> 27430.05
A21: a | B21: 直接费合计 | D21: =D8+D9+D16+D17+D18+D19+D20 -> 1166719.9
A22: b | B22: 施工管理费 | C22: 0.1 | D22: =D21*C22 -> 116671.99
A23: c | B23: 税金 | C23: 0.09 | D23: =(D21+D22)*C23 -> 115505.27
A24: 一 | B24: 装修工程合计 a+b+c | D24: =D21+D22+D23 -> 1398897.1
B25: 报价说明
B26: 1、报价不包含建委及消防报审报验相关手续及费用；
B27: 2、报价中仅包含开荒保洁，不含精细保洁，若需要做精细保洁，需据实增加费用；
B28: 3、报价仅含物业收取管理费，若产生其他收费，需据实增加；
B29: 4、报价不含空气治理及空气检测；
B30: 5、报价不含绿植；

Sheet 工程直接费
A1: =报价汇总!A1 -> Estimation of construction cost for fit-out work
A2: =报价汇总!A2 -> Project: 博彦科技深圳展厅设计施工项目
A3: =报价汇总!A3 -> Project address:深圳
A4: =报价汇总!A4 -> Issue date:2026-07-03
A5: Project code:
A6: No. | B6: id | C6: item_name | D6: item_code | E6: item_type | F6: mat_supply_mode | G6: labor_supply_mode | H6: Description | I6: Unit | J6: Quantity | K6: Unit Price | L6: Total (RMB) | M6: Remarks
A7: 序号 | B7: 数据ID | C7: 数据名称 | D7: 物料编号 | E7: 数据类型 | F7: 物料供应 | G7: 劳务供应 | H7: 项目 | I7: 单位 | J7: 数量 | K7: 单价 | L7: 总计 (人民币) | M7: 备注
A8: I | H8: 直接费合计 | L8: =L9+L11+L60+L62+L65+L67+L69 -> 1166719.9
A9: 1.00 | B9: edbc118a-71fc-438b-aed7-78f70b00aa69 | H9: 拆除工程 | L9: =SUM(L10:L10) -> 31680
A10: 1.01 | B10: 616c85d3-b60d-4268-ba19-3058b9d08a30 | C10: 拆除工程 | E10: 劳务 | F10: 不涉及 | G10: 外包 | H10: 拆除工程 | I10: 平米 | J10: 480 | K10: 66 | L10: =J10*K10 -> 31680
A11: 2.00 | B11: c7783252-0cd5-4f6b-a1c3-c243b6b4b761 | H11: 装饰工程 | L11: =L12+L23+L32+L40+L48+L55 -> 714629
A12: 2.01.00 | B12: e8305092-6250-41d2-83e6-611ffa104f5c | H12: 天花工程 | L12: =SUM(L13:L22) -> 161972.42
A13: 2.01.01 | B13: 17976e53-f047-46a6-a3c4-571124bc3d11 | C13: 提供及安装双层石膏板天花 | E13: 劳务 | F13: 不涉及 | G13: 外包 | H13: 提供及安装双层平顶石膏板天花 | I13: 平米 | J13: 141.07 | K13: 168 | L13: =J13*K13 -> 23699.76
A14: 2.01.02 | B14: e4c0c05c-f9f1-4993-9fa0-971dac0daced | C14: 提供及安装造型石膏板天花 | E14: 劳务 | F14: 不涉及 | G14: 外包 | H14: 提供及安装造型石膏板天花 | I14: 平米 | J14: 198.56 | K14: 228 | L14: =J14*K14 -> 45271.68
A15: 2.01.03 | B15: 1797f696-6139-4c13-aef3-e6021f83718e | C15: 提供及安装白色乳胶漆 | E15: 劳务 | F15: 不涉及 | G15: 外包 | H15: 提供及安装白色乳胶漆 | I15: 平米 | J15: 200.64 | K15: 54 | L15: =J15*K15 -> 10834.56
A16: 2.01.04 | B16: 8c7e19c8-8b04-43c9-83ff-4a092a3eb15a | C16: 提供及安装黑色乳胶漆 | E16: 劳务 | F16: 不涉及 | G16: 外包 | H16: 提供及安装黑色乳胶漆 | I16: 平米 | J16: 138.99 | K16: 57.6 | L16: =J16*K16 -> 8005.82
A17: 2.01.05 | B17: 96136983-dbeb-4411-b4c2-af02110b4404 | C17: 提供及安装镜面不锈钢天花 | E17: 物料 | F17: 自购 | G17: 外包 | H17: 提供及安装圆形不锈钢天花 | I17: 平米 | J17: 46.95 | K17: 1053 | L17: =J17*K17 -> 49438.35
A18: 2.01.06 | B18: f86f32d5-4740-4aee-877d-fe69cedb083c | C18: 提供及安装阳极氧化铝天花 | E18: 物料 | F18: 自购 | G18: 外包 | H18: 提供及安装阳极氧化铝天花 | I18: 平米 | J18: 12.05 | K18: 1053 | L18: =J18*K18 -> 12688.65
A19: 2.01.07 | B19: f9e5fc8e-9e63-4b9a-9102-8936e15fb85c | C19: 提供及安装软膜天花基层 | E19: 劳务 | F19: 不涉及 | G19: 外包 | H19: 提供及安装软膜天花基层 | I19: 平米 | J19: 6.8 | K19: 276 | L19: =J19*K19 -> 1876.8
A20: 2.01.08 | B20: c3896850-cd01-4cab-ad8d-ed6a15a3ee3d | C20: 提供及安装直行灯槽 | E20: 劳务 | F20: 不涉及 | G20: 外包 | H20: 提供及安装直行灯槽 | I20: 米 | J20: 30 | K20: 114 | L20: =J20*K20 -> 3420
A21: 2.01.09 | B21: d474bd52-7a04-4849-9224-13aa1ce40a1f | C21: 提供及安装弧形灯槽 | E21: 劳务 | F21: 不涉及 | G21: 外包 | H21: 提供及安装弧形灯槽 | I21: 米 | J21: 41 | K21: 132 | L21: =J21*K21 -> 5412
A22: 2.01.10 | E22: 劳务 | F22: 不涉及 | G22: 外包 | H22: 天花方钢加固 移动屏位置 | I22: 吨 | J22: 0.12 | K22: 11040 | L22: =J22*K22 -> 1324.8
A23: 2.02.00 | B23: 629436a4-8387-4828-b513-47dc6c293fbb | H23: 隔墙工程 | L23: =SUM(L24:L31) -> 108211.68
A24: 2.02.01 | B24: c2a96c72-37e2-4225-bd22-46675698a68f | C24: 200厚75轻钢龙骨双面双层石膏板隔墙 | E24: 劳务 | F24: 不涉及 | G24: 外包 | H24: 200厚75轻钢龙骨双面双层石膏板隔墙 | I24: 平米 | J24: 53.28 | K24: 234 | L24: =J24*K24 -> 12467.52
A25: 2.02.02 | B25: f6d1d4c9-5433-468e-89b9-0c10abfd2262 | C25: 130厚75轻钢龙骨双面双层石膏板隔墙 | E25: 劳务 | F25: 不涉及 | G25: 外包 | H25: 130厚75轻钢龙骨双面双层石膏板隔墙 | I25: 平米 | J25: 185.36 | K25: 198 | L25: =J25*K25 -> 36701.28
A26: 2.02.03 | B26: 3ae4277b-8239-4dce-8044-3529407805a4 | C26: 500厚双排龙骨双面双层石膏板隔墙 | E26: 劳务 | F26: 不涉及 | G26: 外包 | H26: 500厚双排龙骨双面双层石膏板隔墙 | I26: 平米 | J26: 21.07 | K26: 342 | L26: =J26*K26 -> 7205.94
A27: 2.02.04 | B27: eba24b76-cdbf-4f9b-96cf-943d9cfad862 | C27: 120厚75龙骨双面双层石膏板吊墙 | E27: 劳务 | F27: 不涉及 | G27: 外包 | H27: 120厚75龙骨双面双层石膏板吊墙 | I27: 平米 | J27: 7.11 | K27: 234 | L27: =J27*K27 -> 1663.74
A28: 2.02.05 | B28: 055aaba8-695f-4cb4-aae4-19e32aeaaa9f | C28: 双面双层弧形石膏板隔墙 | E28: 劳务 | F28: 不涉及 | G28: 外包 | H28: 双面双层弧形石膏板隔墙 | I28: 平米 | J28: 114.59 | K28: 306 | L28: =J28*K28 -> 35064.54
A29: 2.02.06 | B29: a4bfa342-bf02-4757-8f42-a22bb8162a94 | C29: 系统玻璃隔断 | E29: 物料 | F29: 自购 | G29: 自施工 | H29: 双层系统玻璃隔断 科沃 | I29: 平米 | J29: 12.34 | K29: 945 | L29: =J29*K29 -> 11661.3
A30: 2.02.07 | B30: 1a79ae79-4f2d-4a66-9cc8-76ffd019514a | C30: 设备带 | E30: 物料 | F30: 自购 | G30: 自施工 | H30: 设备带 | I30: 个 | J30: 2 | K30: 819 | L30: =J30*K30 -> 1638
A31: 2.02.08 | E31: 劳务 | F31: 不涉及 | G31: 外包 | H31: 隔墙加固 | I31: 平米 | J31: 43.08 | K31: 42 | L31: =J31*K31 -> 1809.36
A32: 2.03.00 | B32: 790b4121-3a22-4b11-8923-ab3d135ca053 | H32: 墙面工程 | L32: =SUM(L33:L39) -> 131288.63
A33: 2.03.01 | B33: cc3b4792-6c9b-405a-bbe6-fe5e3bdb4c1d | C33: 提供及安装木饰面 | E33: 物料 | F33: 自购 | G33: 自施工 | H33: 提供及安装木饰面 | I33: 平米 | J33: 23.63 | K33: 567 | L33: =J33*K33 -> 13398.21
A34: 2.03.02 | B34: 5faec624-b31e-4fb7-8b81-7f39c64768fd | C34: 提供及安装阳极氧化铝板 | E34: 物料 | F34: 自购 | G34: 外包 | H34: 提供及安装阳极氧化铝板 | I34: 平米 | J34: 40.75 | K34: 1053 | L34: =J34*K34 -> 42909.75
A35: 2.03.03 | B35: 40a53504-dd79-4623-b832-335c24148ce0 | C35: 提供及安装艺术漆 | E35: 物料 | F35: 自购 | G35: 自施工 | H35: 提供及安装艺术漆 | I35: 平米 | J35: 137.32 | K35: 130.51 | L35: =J35*K35 -> 17921.63 | M35: 国产
A36: 2.03.04 | B36: 8e35d78d-b8dd-423c-b01d-86de35490d4b | C36: 提供及安装直型吸音板 | E36: 物料 | F36: 自购 | G36: 外包 | H36: 提供及安装直型吸音板 | I36: 平米 | J36: 114.31 | K36: 254.11 | L36: =J36*K36 -> 29047.31
A37: 2.03.05 | B37: df799662-0777-4de2-a04e-970ea8e0ace4 | C37: 提供及安装弧形吸音板 | E37: 物料 | F37: 自购 | G37: 外包 | H37: 提供及安装弧形吸音板 | I37: 平米 | J37: 31.16 | K37: 322.51 | L37: =J37*K37 -> 10049.41
A38: 2.03.06 | B38: 374cfa2e-372e-4eb4-8aca-5e0f3559ce1f | C38: 提供及安装墙面乳胶漆 | E38: 劳务 | F38: 不涉及 | G38: 外包 | H38: 提供及安装墙面乳胶漆 | I38: 平米 | J38: 200 | K38: 54 | L38: =J38*K38 -> 10800
A39: 2.03.07 | B39: 2c7f1470-9788-4df1-bc92-bd711484d857 | C39: 提供及安装金属踢脚线 50mm高 | E39: 劳务 | F39: 不涉及 | G39: 外包 | H39: 提供及安装金属踢脚线 50mm高 | I39: 米 | J39: 108.52 | K39: 66 | L39: =J39*K39 -> 7162.32
A40: 2.04.00 | B40: be240c6a-aca5-45c0-94c4-f8c6e3f47be1 | H40: 地面工程 | L40: =SUM(L41:L47) -> 190012.59
...
